W1018 21:19:06.663000 3205986 anaconda3/envs/bdsa/lib/python3.10/site-packages/torch/distributed/run.py:793] 
W1018 21:19:06.663000 3205986 anaconda3/envs/bdsa/lib/python3.10/site-packages/torch/distributed/run.py:793] *****************************************
W1018 21:19:06.663000 3205986 anaconda3/envs/bdsa/lib/python3.10/site-packages/torch/distributed/run.py:793] Setting OMP_NUM_THREADS environment variable for each process to be 1 in default, to avoid your system being overloaded, please further tune the variable for optimal performance in your application as needed. 
W1018 21:19:06.663000 3205986 anaconda3/envs/bdsa/lib/python3.10/site-packages/torch/distributed/run.py:793] *****************************************
/mnt/public/chensiqi/anaconda3/envs/bdsa/bin/python3.10: can't open file '/mnt/public/chensiqi/dual-balance/parallel_examples/run_wan_paro.py': [Errno 2] No such file or directory
/mnt/public/chensiqi/anaconda3/envs/bdsa/bin/python3.10: can't open file '/mnt/public/chensiqi/dual-balance/parallel_examples/run_wan_paro.py': [Errno 2] No such file or directory
/mnt/public/chensiqi/anaconda3/envs/bdsa/bin/python3.10: can't open file '/mnt/public/chensiqi/dual-balance/parallel_examples/run_wan_paro.py': [Errno 2] No such file or directory
/mnt/public/chensiqi/anaconda3/envs/bdsa/bin/python3.10: can't open file '/mnt/public/chensiqi/dual-balance/parallel_examples/run_wan_paro.py': [Errno 2] No such file or directory
/mnt/public/chensiqi/anaconda3/envs/bdsa/bin/python3.10: can't open file '/mnt/public/chensiqi/dual-balance/parallel_examples/run_wan_paro.py': [Errno 2] No such file or directory
/mnt/public/chensiqi/anaconda3/envs/bdsa/bin/python3.10: can't open file '/mnt/public/chensiqi/dual-balance/parallel_examples/run_wan_paro.py': [Errno 2] No such file or directory
/mnt/public/chensiqi/anaconda3/envs/bdsa/bin/python3.10: can't open file '/mnt/public/chensiqi/dual-balance/parallel_examples/run_wan_paro.py': [Errno 2] No such file or directory
/mnt/public/chensiqi/anaconda3/envs/bdsa/bin/python3.10: can't open file '/mnt/public/chensiqi/dual-balance/parallel_examples/run_wan_paro.py': [Errno 2] No such file or directory
E1018 21:19:06.780000 3205986 anaconda3/envs/bdsa/lib/python3.10/site-packages/torch/distributed/elastic/multiprocessing/api.py:869] failed (exitcode: 2) local_rank: 0 (pid: 3206229) of binary: /mnt/public/chensiqi/anaconda3/envs/bdsa/bin/python3.10
Traceback (most recent call last):
  File "/mnt/public/chensiqi/anaconda3/envs/bdsa/bin/torchrun", line 8, in <module>
    sys.exit(main())
  File "/mnt/public/chensiqi/anaconda3/envs/bdsa/lib/python3.10/site-packages/torch/distributed/elastic/multiprocessing/errors/__init__.py", line 355, in wrapper
    return f(*args, **kwargs)
  File "/mnt/public/chensiqi/anaconda3/envs/bdsa/lib/python3.10/site-packages/torch/distributed/run.py", line 919, in main
    run(args)
  File "/mnt/public/chensiqi/anaconda3/envs/bdsa/lib/python3.10/site-packages/torch/distributed/run.py", line 910, in run
    elastic_launch(
  File "/mnt/public/chensiqi/anaconda3/envs/bdsa/lib/python3.10/site-packages/torch/distributed/launcher/api.py", line 138, in __call__
    return launch_agent(self._config, self._entrypoint, list(args))
  File "/mnt/public/chensiqi/anaconda3/envs/bdsa/lib/python3.10/site-packages/torch/distributed/launcher/api.py", line 269, in launch_agent
    raise ChildFailedError(
torch.distributed.elastic.multiprocessing.errors.ChildFailedError: 
============================================================
parallel_examples/run_wan_paro.py FAILED
------------------------------------------------------------
Failures:
[1]:
  time      : 2025-10-18_21:19:06
  host      : is-dbk5hvtyuoby6of7-devmachine-0
  rank      : 1 (local_rank: 1)
  exitcode  : 2 (pid: 3206230)
  error_file: <N/A>
  traceback : To enable traceback see: https://pytorch.org/docs/stable/elastic/errors.html
[2]:
  time      : 2025-10-18_21:19:06
  host      : is-dbk5hvtyuoby6of7-devmachine-0
  rank      : 2 (local_rank: 2)
  exitcode  : 2 (pid: 3206231)
  error_file: <N/A>
  traceback : To enable traceback see: https://pytorch.org/docs/stable/elastic/errors.html
[3]:
  time      : 2025-10-18_21:19:06
  host      : is-dbk5hvtyuoby6of7-devmachine-0
  rank      : 3 (local_rank: 3)
  exitcode  : 2 (pid: 3206232)
  error_file: <N/A>
  traceback : To enable traceback see: https://pytorch.org/docs/stable/elastic/errors.html
[4]:
  time      : 2025-10-18_21:19:06
  host      : is-dbk5hvtyuoby6of7-devmachine-0
  rank      : 4 (local_rank: 4)
  exitcode  : 2 (pid: 3206233)
  error_file: <N/A>
  traceback : To enable traceback see: https://pytorch.org/docs/stable/elastic/errors.html
[5]:
  time      : 2025-10-18_21:19:06
  host      : is-dbk5hvtyuoby6of7-devmachine-0
  rank      : 5 (local_rank: 5)
  exitcode  : 2 (pid: 3206234)
  error_file: <N/A>
  traceback : To enable traceback see: https://pytorch.org/docs/stable/elastic/errors.html
[6]:
  time      : 2025-10-18_21:19:06
  host      : is-dbk5hvtyuoby6of7-devmachine-0
  rank      : 6 (local_rank: 6)
  exitcode  : 2 (pid: 3206235)
  error_file: <N/A>
  traceback : To enable traceback see: https://pytorch.org/docs/stable/elastic/errors.html
[7]:
  time      : 2025-10-18_21:19:06
  host      : is-dbk5hvtyuoby6of7-devmachine-0
  rank      : 7 (local_rank: 7)
  exitcode  : 2 (pid: 3206236)
  error_file: <N/A>
  traceback : To enable traceback see: https://pytorch.org/docs/stable/elastic/errors.html
------------------------------------------------------------
Root Cause (first observed failure):
[0]:
  time      : 2025-10-18_21:19:06
  host      : is-dbk5hvtyuoby6of7-devmachine-0
  rank      : 0 (local_rank: 0)
  exitcode  : 2 (pid: 3206229)
  error_file: <N/A>
  traceback : To enable traceback see: https://pytorch.org/docs/stable/elastic/errors.html
============================================================
